Workbook
Name Slicer_assigned_analyst: #N/A
Name Slicer_category: #N/A
Name Slicer_day_of_week: #N/A
Name Slicer_priority: #N/A
Name Slicer_resolution_time_hrs: #N/A

Sheet Summary dashboard

Sheet Data & calculations
A1: ticket_id | B1: submission_date | C1: resolution_date | D1: category | E1: assigned_analyst | F1: description | G1: priority | H1: resolution time(hrs) | I1: day of week | J1: month name | K1: hour of submission | L1: Keyword detection
A2: TICKET-1000 | B2: 45835.942 | C2: 45836.157 | D2: Other | E2: Toni Wiley | F2: Dream part subject until full. Brother century suddenly above. Six eight benefit animal move best. | G2: High | H2: =(help_desk_tickets[[#This Row],[resolution_date]]-help_desk_tickets[[#This Row],[submission_date]])*24 -> 5.1735194 | I2: =TEXT(help_desk_tickets[[#This Row],[submission_date]],"ddd") -> Fri | J2: =TEXT(help_desk_tickets[[#This Row],[submission_date]],"mmm") -> Jun | K2: =HOUR(help_desk_tickets[[#This Row],[submission_date]]) -> 22 | L2: =IF(ISNUMBER(SEARCH("password",F2)),"Password Issue",IF(ISNUMBER(SEARCH("network",F2)),"Network issue",IF(ISNUMBER(SEARCH("internet",F2)),"Network issues",IF(ISNUMBER(SEARCH("crashing",F2)),"Login issue",IF(ISNUMBER(SEARCH("stuck",F2)),"Performance issue","Other"))))) -> Other
A3: TICKET-1001 | B3: 45901.811 | C3: 45903.304 | D3: Software | E3: Tanya Jones | F3: Application X is crashing every time I open it. Lead how phone also score player later blue. | G3: Medium | H3: =(help_desk_tickets[[#This Row],[resolution_date]]-help_desk_tickets[[#This Row],[submission_date]])*24 -> 35.835203 | I3: =TEXT(help_desk_tickets[[#This Row],[submission_date]],"ddd") -> Mon | J3: =TEXT(help_desk_tickets[[#This Row],[submission_date]],"mmm") -> Sep | K3: =HOUR(help_desk_tickets[[#This Row],[submission_date]]) -> 19 | L3: =IF(ISNUMBER(SEARCH("password",F3)),"Password Issue",IF(ISNUMBER(SEARCH("network",F3)),"Network issue",IF(ISNUMBER(SEARCH("internet",F3)),"Network issues",IF(ISNUMBER(SEARCH("crashing",F3)),"Login issue",IF(ISNUMBER(SEARCH("stuck",F3)),"Performance issue","Other"))))) -> Login issue
A4: TICKET-1002 | B4: 45904.397 | C4: 45905.993 | D4: Other | E4: Sheila Ball | F4: Black attack cold would page. Reality she war a chance. Physical hour Mr item red agreement for. | G4: Medium | H4: =(help_desk_tickets[[#This Row],[resolution_date]]-help_desk_tickets[[#This Row],[submission_date]])*24 -> 38.309437 | I4: =TEXT(help_desk_tickets[[#This Row],[submission_date]],"ddd") -> Thu | J4: =TEXT(help_desk_tickets[[#This Row],[submission_date]],"mmm") -> Sep | K4: =HOUR(help_desk_tickets[[#This Row],[submission_date]]) -> 9 | L4: =IF(ISNUMBER(SEARCH("password",F4)),"Password Issue",IF(ISNUMBER(SEARCH("network",F4)),"Network issue",IF(ISNUMBER(SEARCH("internet",F4)),"Network issues",IF(ISNUMBER(SEARCH("crashing",F4)),"Login issue",IF(ISNUMBER(SEARCH("stuck",F4)),"Performance issue","Other"))))) -> Other
A5: TICKET-1003 | B5: 45866.741 | C5: 45867.068 | D5: Hardware | E5: Cynthia Rich | F5: My laptop's keyboard isn't working properly, some keys are stuck. Tree culture above effort more national whether. | G5: High | H5: =(help_desk_tickets[[#This Row],[resolution_date]]-help_desk_tickets[[#This Row],[submission_date]])*24 -> 7.8459175 | I5: =TEXT(help_desk_tickets[[#This Row],[submission_date]],"ddd") -> Mon | J5: =TEXT(help_desk_tickets[[#This Row],[submission_date]],"mmm") -> Jul | K5: =HOUR(help_desk_tickets[[#This Row],[submission_date]]) -> 17 | L5: =IF(ISNUMBER(SEARCH("password",F5)),"Password Issue",IF(ISNUMBER(SEARCH("network",F5)),"Network issue",IF(ISNUMBER(SEARCH("internet",F5)),"Network issues",IF(ISNUMBER(SEARCH("crashing",F5)),"Login issue",IF(ISNUMBER(SEARCH("stuck",F5)),"Performance issue","Other"))))) -> Performance issue
A6: TICKET-1004 | B6: 45903.907 | C6: 45904.287 | D6: Software | E6: Janice Burns | F6: Application X is crashing every time I open it. Order wrong fight foreign bad house pick. | G6: High | H6: =(help_desk_tickets[[#This Row],[resolution_date]]-help_desk_tickets[[#This Row],[submission_date]])*24 -> 9.1162586 | I6: =TEXT(help_desk_tickets[[#This Row],[submission_date]],"ddd") -> Wed | J6: =TEXT(help_desk_tickets[[#This Row],[submission_date]],"mmm") -> Sep | K6: =HOUR(help_desk_tickets[[#This Row],[submission_date]]) -> 21 | L6: =IF(ISNUMBER(SEARCH("password",F6)),"Password Issue",IF(ISNUMBER(SEARCH("network",F6)),"Network issue",IF(ISNUMBER(SEARCH("internet",F6)),"Network issues",IF(ISNUMBER(SEARCH("crashing",F6)),"Login issue",IF(ISNUMBER(SEARCH("stuck",F6)),"Performance issue","Other"))))) -> Login issue
A7: TICKET-1005 | B7: 45873.856 | C7: 45879.412 | D7: Software | E7: Sheila Ball | F7: Application X is crashing every time I open it. Sport should network realize relate very voice. | G7: Low | H7: =(help_desk_tickets[[#This Row],[resolution_date]]-help_desk_tickets[[#This Row],[submission_date]])*24 -> 133.33369 | I7: =TEXT(help_desk_tickets[[#This Row],[submission_date]],"ddd") -> Mon | J7: =TEXT(help_desk_tickets[[#This Row],[submission_date]],"mmm") -> Aug | K7: =HOUR(help_desk_tickets[[#This Row],[submission_date]]) -> 20 | L7: =IF(ISNUMBER(SEARCH("password",F7)),"Password Issue",IF(ISNUMBER(SEARCH("network",F7)),"Network issue",IF(ISNUMBER(SEARCH("internet",F7)),"Network issues",IF(ISNUMBER(SEARCH("crashing",F7)),"Login issue",IF(ISNUMBER(SEARCH("stuck",F7)),"Performance issue","Other"))))) -> Network issue
A8: TICKET-1006 | B8: 45891.443 | C8: 45892.592 | D8: Access | E8: Autumn Ryan | F8: I'm locked out of my account and can't reset my password. If rather year suffer wrong. | G8: Low | H8: =(help_desk_tickets[[#This Row],[resolution_date]]-help_desk_tickets[[#This Row],[submission_date]])*24 -> 27.559389 | I8: =TEXT(help_desk_tickets[[#This Row],[submission_date]],"ddd") -> Fri | J8: =TEXT(help_desk_tickets[[#This Row],[submission_date]],"mmm") -> Aug | K8: =HOUR(help_desk_tickets[[#This Row],[submission_date]]) -> 10 | L8: =IF(ISNUMBER(SEARCH("password",F8)),"Password Issue",IF(ISNUMBER(SEARCH("network",F8)),"Network issue",IF(ISNUMBER(SEARCH("internet",F8)),"Network issues",IF(ISNUMBER(SEARCH("crashing",F8)),"Login issue",IF(ISNUMBER(SEARCH("stuck",F8)),"Performance issue","Other"))))) -> Password Issue
A9: TICKET-1007 | B9: 45843.322 | C9: 45847.852 | D9: Software | E9: Amanda White | F9: Application X is crashing every time I open it. Here bill leg region training. Grow new may. | G9: Low | H9: =(help_desk_tickets[[#This Row],[resolution_date]]-help_desk_tickets[[#This Row],[submission_date]])*24 -> 108.71431 | I9: =TEXT(help_desk_tickets[[#This Row],[submission_date]],"ddd") -> Sat | J9: =TEXT(help_desk_tickets[[#This Row],[submission_date]],"mmm") -> Jul | K9: =HOUR(help_desk_tickets[[#This Row],[submission_date]]) -> 7 | L9: =IF(ISNUMBER(SEARCH("password",F9)),"Password Issue",IF(ISNUMBER(SEARCH("network",F9)),"Network issue",IF(ISNUMBER(SEARCH("internet",F9)),"Network issues",IF(ISNUMBER(SEARCH("crashing",F9)),"Login issue",IF(ISNUMBER(SEARCH("stuck",F9)),"Performance issue","Other"))))) -> Login issue
A10: TICKET-1008 | B10: 45845.695 | C10: 45846.42 | D10: Hardware | E10: Amanda White | F10: My laptop's keyboard isn't working properly, some keys are stuck. Common maintain theory involve ok detail. | G10: Medium | H10: =(help_desk_tickets[[#This Row],[resolution_date]]-help_desk_tickets[[#This Row],[submission_date]])*24 -> 17.387358 | I10: =TEXT(help_desk_tickets[[#This Row],[submission_date]],"ddd") -> Mon | J10: =TEXT(help_desk_tickets[[#This Row],[submission_date]],"mmm") -> Jul | K10: =HOUR(help_desk_tickets[[#This Row],[submission_date]]) -> 16 | L10: =IF(ISNUMBER(SEARCH("password",F10)),"Password Issue",IF(ISNUMBER(SEARCH("network",F10)),"Network issue",IF(ISNUMBER(SEARCH("internet",F10)),"Network issues",IF(ISNUMBER(SEARCH("crashing",F10)),"Login issue",IF(ISNUMBER(SEARCH("stuck",F10)),"Performance issue","Other"))))) -> Performance issue
A11: TICKET-1009 | B11: 45910.618 | C11: 45911.832 | D11: Software | E11: Sheila Ball | F11: Application X is crashing every time I open it. Responsibility again recently traditional word. | G11: Medium | H11: =(help_desk_tickets[[#This Row],[resolution_date]]-help_desk_tickets[[#This Row],[submission_date]])*24 -> 29.151189 | I11: =TEXT(help_desk_tickets[[#This Row],[submission_date]],"ddd") -> Wed | J11: =TEXT(help_desk_tickets[[#This Row],[submission_date]],"mmm") -> Sep | K11: =HOUR(help_desk_tickets[[#This Row],[submission_date]]) -> 14 | L11: =IF(ISNUMBER(SEARCH("password",F11)),"Password Issue",IF(ISNUMBER(SEARCH("network",F11)),"Network issue",IF(ISNUMBER(SEARCH("internet",F11)),"Network issues",IF(ISNUMBER(SEARCH("crashing",F11)),"Login issue",IF(ISNUMBER(SEARCH("stuck",F11)),"Performance issue","Other"))))) -> Login issue
A12: TICKET-1010 | B12: 45896.556 | C12: 45902.686 | D12: Software | E12: Adam Stone | F12: Application X is crashing every time I open it. Structure this woman born. | G12: Low | H12: =(help_desk_tickets[[#This Row],[resolution_date]]-help_desk_tickets[[#This Row],[submission_date]])*24 -> 147.14154 | I12: =TEXT(help_desk_tickets[[#This Row],[submission_date]],"ddd") -> Wed | J12: =TEXT(help_desk_tickets[[#This Row],[submission_date]],"mmm") -> Aug | K12: =HOUR(help_desk_tickets[[#This Row],[submission_date]]) -> 13 | L12: =IF(ISNUMBER(SEARCH("password",F12)),"Password Issue",IF(ISNUMBER(SEARCH("network",F12)),"Network issue",IF(ISNUMBER(SEARCH("internet",F12)),"Network issues",IF(ISNUMBER(SEARCH("crashing",F12)),"Login issue",IF(ISNUMBER(SEARCH("stuck",F12)),"Performance issue","Other"))))) -> Login issue
A13: TICKET-1011 | B13: 45832.081 | C13: 45832.241 | D13: Network | E13: Natasha Harris | F13: Can't connect to the Wi-Fi. It's showing 'No internet access'. Maintain without college strong few not week. | G13: High | H13: =(help_desk_tickets[[#This Row],[resolution_date]]-help_desk_tickets[[#This Row],[submission_date]])*24 -> 3.8372253 | I13: =TEXT(help_desk_tickets[[#This Row],[submission_date]],"ddd") -> Tue | J13: =TEXT(help_desk_tickets[[#This Row],[submission_date]],"mmm") -> Jun | K13: =HOUR(help_desk_tickets[[#This Row],[submission_date]]) -> 1 | L13: =IF(ISNUMBER(SEARCH("password",F13)),"Password Issue",IF(ISNUMBER(SEARCH("network",F13)),"Network issue",IF(ISNUMBER(SEARCH("internet",F13)),"Network issues",IF(ISNUMBER(SEARCH("crashing",F13)),"Login issue",IF(ISNUMBER(SEARCH("stuck",F13)),"Performance issue","Other"))))) -> Network issues
... A151: TICKET-1149 | B151: 45869.175 | C151: 45870.176 | D151: Hardware | E151: Toni Wiley | F151: My laptop's keyboard isn't working properly, some keys are stuck. Event pattern factor deep manager work. | G151: Medium | H151: =(help_desk_tickets[[#This Row],[resolution_date]]-help_desk_tickets[[#This Row],[submission_date]])*24 -> 24.012929 | I151: =TEXT(help_desk_tickets[[#This Row],[submission_date]],"ddd") -> Thu | J151: =TEXT(help_desk_tickets[[#This Row],[submission_date]],"mmm") -> Jul | K151: =HOUR(help_desk_tickets[[#This Row],[submission_date]]) -> 4 | L151: =IF(ISNUMBER(SEARCH("password",F151)),"Password Issue",IF(ISNUMBER(SEARCH("network",F151)),"Network issue",IF(ISNUMBER(SEARCH("internet",F151)),"Network issues",IF(ISNUMBER(SEARCH("crashing",F151)),"Login issue",IF(ISNUMBER(SEARCH("stuck",F151)),"Performance issue","Other"))))) -> Performance issue

Sheet Detailed analysis
A1: TICKET TRENDS
A3: Day of week | B3: Count of ticket_id
A4: Sun | B4: 26
A5: Mon | B5: 19
A6: Tue | B6: 22
A7: Wed | B7: 24
A8: Thu | B8: 23
A9: Fri | B9: 16
A10: Sat | B10: 20
A11: Grand Total | B11: 150
A20: Month | B20: Count of ticket_id
A21: Jun | B21: 27
A22: Jul | B22: 51
A23: Aug | B23: 45
A24: Sep | B24: 27
A25: Grand Total | B25: 150
A42: RESOLUTION TIME ANALYSIS
A44: Priority | B44: Average of resolution time(hrs)
A45: Critical | B45: 2.2080753
A46: High | B46: 6.6783505
A47: Low | B47: 105.14096
A48: Medium | B48: 27.309928
A49: Grand Total | B49: 53.296613
A61: Category | B61: Average of resolution time(hrs)
A62: Access | B62: 44.386787
A63: Billing | B63: 62.616182
A64: Hardware | B64: 42.63662
A65: Network | B65: 50.114464
A66: Other | B66: 51.542925
A67: Security | B67: 97.824123
A68: Software | B68: 54.683194
A69: Grand Total | B69: 53.296613
A82: TOP PROBLEMS
A85: Count of password keyword | B85: =COUNTIF('Data & calculations'!L:L,"*password*") -> 15
A86: Count of network keyword | B86: =COUNTIF('Data & calculations'!L:L,"*network*") -> 25
A87: Count of login keyword | B87: =COUNTIF('Data & calculations'!L:L,"*login*") -> 50
A88: Count of performance keyword | B88: =COUNTIF('Data & calculations'!L:L,"*Performance*") -> 24
A89: Count of others keyword | B89: =COUNTIF('Data & calculations'!L:L,"*other*") -> 36
A109: ANALYST PERFORMANCE
A112: Assigned analyst | B112: Average of resolution time(hrs)
...

Sheet Recommendations
A1: 1. Automate Repetitive Issues
A3: Implement a self-service password reset system to reduce access-related tickets.
A5: Automate common requests like software installation and account unlocks.
A9: 🌐 2. Improve Network Reliability
A11: Deploy network monitoring tools to detect and resolve issues proactively.
A13: Upgrade infrastructure to reduce frequent connectivity complaints.
A17: 👨‍💻 3. Optimize Analyst Performance
A19: Provide training and support for analysts with higher resolution times.
A21: Introduce performance tracking metrics to improve accountability.
A25: ⏰ 4. Resource Planning & Staffing
A27: Increase staffing during peak hours and high-volume days.
A29: Implement shift planning based on ticket trends to balance workload.
... A59: Use insights to continuously improve IT operations.
